<?xml version="1.0"?>
<robot name="elevator">
<!--WingA Elevator-->

    <gazebo>
        <gravity>0</gravity>
        <plugin name="gazebo_ros_control" filename="libgazebo_ros_control.so">
		<robotSimType>gazebo_ros_control/DefaultRobotHWSim</robotSimType>
        </plugin>
    </gazebo>

    <gazebo reference="world">
    <gravity>0</gravity>
        <static>true</static>
    </gazebo>
    
    <gazebo reference="shaft">
        <collision>
            <max_contact>0</max_contact>
        </collision>
    	<static>true</static>
    </gazebo>    

    <gazebo reference="car">
        <gravity>0</gravity>
    </gazebo>    

    <gazebo reference="car_door_left">
        <gravity>0</gravity>
    </gazebo>    

    <gazebo reference="car_door_right">
        <gravity>0</gravity>
    </gazebo>    

	<gazebo>
		<plugin name="joint_state_publisher" filename="libgazebo_ros_joint_state_publisher.so">
			<jointName>floor</jointName>
            <jointName>car_door_left_joint</jointName>
            <jointName>car_door_right_joint</jointName>
            <jointName>lobby_door_left_joint</jointName>
            <jointName>lobby_door_right_joint</jointName>
            <jointName>first_door_left_joint</jointName>
            <jointName>first_door_right_joint</jointName>
            <jointName>second_door_left_joint</jointName>
            <jointName>second_door_right_joint</jointName>
		</plugin>
	</gazebo>

    <link name="world"/>

    <link name="shaft">
 	    <inertial>
            <origin rpy="0 0 0" xyz="0 0 0"/>
            <mass value="2000" />
            <inertia ixx="1.0" ixy="0.0" ixz="0.0" iyy="1.0" iyz="0.0" izz="1.0"/>
        </inertial>
        <collision name="collision">
            <origin rpy="0.0 0 0" xyz="0 0 0"/>
            <geometry>
                <mesh filename="package://elevator_control/models/wingA_elevator/shaft.dae" />
            </geometry>
        </collision>        
        <visual name="visual">
            <origin rpy="0.0 0 0" xyz="0 0 0"/>
            <geometry>
                <mesh filename="package://elevator_control/models/wingA_elevator/shaft.dae" />
            </geometry>
        </visual>
        <surface>
            <friction>
                <ode>
                  <mu>0</mu>
                    <mu2>0</mu2>
                </ode>
            </friction>
        </surface>        
	</link>

    <joint name="world_shaft" type="fixed">
        <origin xyz="0 0 0.0" rpy="0.0 0.0 0.0"/>
        <parent link="world" />
        <child link="shaft" />
    </joint>

    <link name="car">
 	    <inertial>
            <origin rpy="0 0 0" xyz="0 0 0"/>
            <mass value="100" />
            <inertia ixx="1.0" ixy="0.0" ixz="0.0" iyy="1.0" iyz="0.0" izz="1.0"/>
        </inertial>
        <collision>
            <origin rpy="0.0 0 0" xyz="0 0 0"/>
            <geometry>
                <mesh filename="package://elevator_control/models/wingA_elevator/car.dae" />
            </geometry>
        </collision>
        <visual>
            <origin rpy="0.0 0 0" xyz="0 0 0"/>
            <geometry>
                <mesh filename="package://elevator_control/models/wingA_elevator/car.dae" />
            </geometry>
        </visual>
	</link>

    <joint name="floor" type="prismatic">
        <origin xyz="0 0 0" rpy="0.0 0.0 0.0"/>
        <parent link="shaft" />
        <child link="car" />
        <axis xyz="0 0 1" />
        <limit effort="10000" lower="0.0" upper="8.0" velocity="0.5" />
	    <dynamics damping="200" />
    </joint>    

    <transmission name="floor_tran">
		<type>transmission_interface/SimpleTransmission</type>
		<joint name="floor">
			<hardwareInterface>hardware_interface/EffortJointInterface</hardwareInterface>
		</joint>
		<actuator name="floor_motor">
			<hardwareInterface>hardware_interface/EffortJointInterface</hardwareInterface>
			<mechanicalReduction>1</mechanicalReduction>
		</actuator>
	</transmission>    

<!-- Car Doors -->

    <link name="car_door_left">
 	    <inertial>
            <origin rpy="0 0 0" xyz="0 0 0"/>
            <mass value="100" />
            <inertia ixx="1.0" ixy="0.0" ixz="0.0" iyy="1.0" iyz="0.0" izz="1.0"/>
        </inertial>
        <collision>
            <origin rpy="0.0 0 0" xyz="0 0 0"/>
            <geometry>
                <mesh filename="package://elevator_control/models/wingA_elevator/car_door_left.dae" />
            </geometry>
        </collision>
        <visual>
            <origin rpy="0.0 0 0" xyz="0 0 0"/>
            <geometry>
                <mesh filename="package://elevator_control/models/wingA_elevator/car_door_left.dae" />
            </geometry>
        </visual>
	</link>

    <joint name="car_door_left_joint" type="prismatic">
        <origin xyz="0 0 0" rpy="0.0 0.0 0.0"/>
        <parent link="car" />
        <child link="car_door_left" />
        <axis xyz="1 0 0" />
        <limit effort="100" lower="-0.5" upper="0.0" velocity="0.1" />
	<dynamics damping="100.0" />
    </joint>
link
    <transmission name="car_door_left_tran">
		<type>transmission_interface/SimpleTransmission</type>
		<joint name="car_door_left_joint">
			<hardwareInterface>hardware_interface/EffortJointInterface</hardwareInterface>
		</joint>
		<actuator name="car_door_left_motor">
			<hardwareInterface>hardware_interface/EffortJointInterface</hardwareInterface>
			<mechanicalReduction>1</mechanicalReduction>
		</actuator>
	</transmission>


    <link name="car_door_right">
 	    <inertial>
            <origin rpy="0 0 0" xyz="0 0 0"/>
            <mass value="100" />
            <inertia ixx="1.0" ixy="0.0" ixz="0.0" iyy="1.0" iyz="0.0" izz="1.0"/>
        </inertial>
        <collision>
            <origin rpy="0.0 0 0" xyz="0 0 0"/>
            <geometry>
                <mesh filename="package://elevator_control/models/wingA_elevator/car_door_right.dae" />
            </geometry>
        </collision>
        <visual>
            <origin rpy="0.0 0 0" xyz="0 0 0"/>
            <geometry>
                <mesh filename="package://elevator_control/models/wingA_elevator/car_door_right.dae" />
            </geometry>
        </visual>
	</link>

    <joint name="car_door_right_joint" type="prismatic">
        <origin xyz="0 0 0" rpy="0.0 0.0 0.0"/>
        <parent link="car" />
        <child link="car_door_right" />
        <axis xyz="1 0 0" />
        <limit effort="100" lower="0.0" upper="0.5" velocity="0.1" />
	<dynamics damping="100.0" />
    </joint>     

    <transmission name="car_door_right_tran">
		<type>transmission_interface/SimpleTransmission</type>
		<joint name="car_door_right_joint">
			<hardwareInterface>hardware_interface/EffortJointInterface</hardwareInterface>
		</joint>
		<actuator name="car_door_right_motor">
			<hardwareInterface>hardware_interface/EffortJointInterface</hardwareInterface>
			<mechanicalReduction>1</mechanicalReduction>
		</actuator>
	</transmission>

<!-- Lobby Doors -->


    <link name="lobby_door_left">
 	    <inertial>
            <origin rpy="0 0 0" xyz="0 0 0"/>
            <mass value="100" />
            <inertia ixx="1.0" ixy="0.0" ixz="0.0" iyy="1.0" iyz="0.0" izz="1.0"/>
        </inertial>
        <collision>
            <origin rpy="0.0 0 0" xyz="0 0 0"/>
            <geometry>
                <mesh filename="package://elevator_control/models/wingA_elevator/lobby_door_left.dae" />
            </geometry>
        </collision>
        <visual>
            <origin rpy="0.0 0 0" xyz="0 0 0"/>
            <geometry>
                <mesh filename="package://elevator_control/models/wingA_elevator/lobby_door_left.dae" />
            </geometry>
        </visual>
	</link>

    <joint name="lobby_door_left_joint" type="prismatic">
        <origin xyz="0 0 0" rpy="0.0 0.0 0.0"/>
        <parent link="shaft" />
        <child link="lobby_door_left" />
        <axis xyz="1 0 0" />
        <limit effort="100" lower="-0.5" upper="0.0" velocity="0.1" />
	<dynamics damping="100.0" />
    </joint>


    <transmission name="lobby_door_left_tran">
		<type>transmission_interface/SimpleTransmission</type>
		<joint name="lobby_door_left_joint">
			<hardwareInterface>hardware_interface/EffortJointInterface</hardwareInterface>
		</joint>
		<actuator name="lobby_door_left_motor">
			<hardwareInterface>hardware_interface/EffortJointInterface</hardwareInterface>
			<mechanicalReduction>1</mechanicalReduction>
		</actuator>
	</transmission>

    <link name="lobby_door_right">
 	    <inertial>
            <origin rpy="0 0 0" xyz="0 0 0"/>
            <mass value="100" />
            <inertia ixx="1.0" ixy="0.0" ixz="0.0" iyy="1.0" iyz="0.0" izz="1.0"/>
        </inertial>
        <collision>
            <origin rpy="0.0 0 0" xyz="0 0 0"/>
            <geometry>
                <mesh filename="package://elevator_control/models/wingA_elevator/lobby_door_right.dae" />
            </geometry>
        </collision>
        <visual>
            <origin rpy="0.0 0 0" xyz="0 0 0"/>
            <geometry>
                <mesh filename="package://elevator_control/models/wingA_elevator/lobby_door_right.dae" />
            </geometry>
        </visual>
	</link>

    <joint name="lobby_door_right_joint" type="prismatic">
        <origin xyz="0 0 0" rpy="0.0 0.0 0.0"/>
        <parent link="shaft" />
        <child link="lobby_door_right" />
        <axis xyz="1 0 0" />
        <limit effort="100" lower="0.0" upper="0.5" velocity="0.1" />
	<dynamics damping="100.0" />
    </joint> 

    <transmission name="lobby_door_right_tran">
		<type>transmission_interface/SimpleTransmission</type>
		<joint name="lobby_door_right_joint">
			<hardwareInterface>hardware_interface/EffortJointInterface</hardwareInterface>
		</joint>
		<actuator name="lobby_door_right_motor">
			<hardwareInterface>hardware_interface/EffortJointInterface</hardwareInterface>
			<mechanicalReduction>1</mechanicalReduction>
		</actuator>
	</transmission>

<!-- First Floor Doors -->
    <link name="first_door_left">
 	    <inertial>
            <origin rpy="0 0 0" xyz="0 0 0"/>
            <mass value="100" />
            <inertia ixx="1.0" ixy="0.0" ixz="0.0" iyy="1.0" iyz="0.0" izz="1.0"/>
        </inertial>
        <collision>
            <origin rpy="0.0 0 0" xyz="0 0 0"/>
            <geometry>
                <mesh filename="package://elevator_control/models/wingA_elevator/first_door_left.dae" />
            </geometry>
        </collision>
        <visual>
            <origin rpy="0.0 0 0" xyz="0 0 0"/>
            <geometry>
                <mesh filename="package://elevator_control/models/wingA_elevator/first_door_left.dae" />
            </geometry>
        </visual>
	</link>

    <joint name="first_door_left_joint" type="prismatic">
        <origin xyz="0 0 0" rpy="0.0 0.0 0.0"/>
        <parent link="shaft" />
        <child link="first_door_left" />
        <axis xyz="1 0 0" />
        <limit effort="100" lower="-0.5" upper="0.0" velocity="0.1" />
	<dynamics damping="100.0" />
    </joint>

    <transmission name="first_door_left_tran">
		<type>transmission_interface/SimpleTransmission</type>
		<joint name="first_door_left_joint">
			<hardwareInterface>hardware_interface/EffortJointInterface</hardwareInterface>
		</joint>
		<actuator name="first_door_left_motor">
			<hardwareInterface>hardware_interface/EffortJointInterface</hardwareInterface>
			<mechanicalReduction>1</mechanicalReduction>
		</actuator>
	</transmission>

    <link name="first_door_right">
 	    <inertial>
            <origin rpy="0 0 0" xyz="0 0 0"/>
            <mass value="100" />
            <inertia ixx="1.0" ixy="0.0" ixz="0.0" iyy="1.0" iyz="0.0" izz="1.0"/>
        </inertial>
        <collision>
            <origin rpy="0.0 0 0" xyz="0 0 0"/>
            <geometry>
                <mesh filename="package://elevator_control/models/wingA_elevator/first_door_right.dae" />
            </geometry>
        </collision>
        <visual>
            <origin rpy="0.0 0 0" xyz="0 0 0"/>
            <geometry>
                <mesh filename="package://elevator_control/models/wingA_elevator/first_door_right.dae" />
            </geometry>
        </visual>
	</link>

    <joint name="first_door_right_joint" type="prismatic">
        <origin xyz="0 0 0" rpy="0.0 0.0 0.0"/>
        <parent link="shaft" />
        <child link="first_door_right" />
        <axis xyz="1 0 0" />
        <limit effort="100" lower="0.0" upper="0.5" velocity="0.1" />
	<dynamics damping="100.0" />
    </joint> 

    <transmission name="first_door_right_tran">
		<type>transmission_interface/SimpleTransmission</type>
		<joint name="first_door_right_joint">
			<hardwareInterface>hardware_interface/EffortJointInterface</hardwareInterface>
		</joint>
		<actuator name="first_door_right_motor">
			<hardwareInterface>hardware_interface/EffortJointInterface</hardwareInterface>
			<mechanicalReduction>1</mechanicalReduction>
		</actuator>
	</transmission>

<!-- Second Floor Doors -->
    <link name="second_door_left">
 	    <inertial>
            <origin rpy="0 0 0" xyz="0 0 0"/>
            <mass value="100" />
            <inertia ixx="1.0" ixy="0.0" ixz="0.0" iyy="1.0" iyz="0.0" izz="1.0"/>
        </inertial>
        <collision>
            <origin rpy="0.0 0 0" xyz="0 0 0"/>
            <geometry>
                <mesh filename="package://elevator_control/models/wingA_elevator/second_door_left.dae" />
            </geometry>
        </collision>
        <visual>
            <origin rpy="0.0 0 0" xyz="0 0 0"/>
            <geometry>
                <mesh filename="package://elevator_control/models/wingA_elevator/second_door_left.dae" />
            </geometry>
        </visual>
	</link>

    <joint name="second_door_left_joint" type="prismatic">
        <origin xyz="0 0 0" rpy="0.0 0.0 0.0"/>
        <parent link="shaft" />
        <child link="second_door_left" />
        <axis xyz="1 0 0" />
        <limit effort="100" lower="-0.5" upper="0.0" velocity="0.1" />
	<dynamics damping="100.0" />
    </joint>

    <transmission name="second_door_left_tran">
		<type>transmission_interface/SimpleTransmission</type>
		<joint name="second_door_left_joint">
			<hardwareInterface>hardware_interface/EffortJointInterface</hardwareInterface>
		</joint>
		<actuator name="second_door_left_motor">
			<hardwareInterface>hardware_interface/EffortJointInterface</hardwareInterface>
			<mechanicalReduction>1</mechanicalReduction>
		</actuator>
	</transmission>    

    <link name="second_door_right">
 	    <inertial>
            <origin rpy="0 0 0" xyz="0 0 0"/>
            <mass value="100" />
            <inertia ixx="1.0" ixy="0.0" ixz="0.0" iyy="1.0" iyz="0.0" izz="1.0"/>
        </inertial>
        <collision>
            <origin rpy="0.0 0 0" xyz="0 0 0"/>
            <geometry>
                <mesh filename="package://elevator_control/models/wingA_elevator/second_door_right.dae" />
            </geometry>
        </collision>
        <visual>
            <origin rpy="0.0 0 0" xyz="0 0 0"/>
            <geometry>
                <mesh filename="package://elevator_control/models/wingA_elevator/second_door_right.dae" />
            </geometry>
        </visual>
	</link>

    <joint name="second_door_right_joint" type="prismatic">
        <origin xyz="0 0 0" rpy="0.0 0.0 0.0"/>
        <parent link="shaft" />
        <child link="second_door_right" />
        <axis xyz="1 0 0" />
        <limit effort="100" lower="0.0" upper="0.5" velocity="0.1" />
	<dynamics damping="100.0" />
    </joint> 

    <transmission name="second_door_right_tran">
		<type>transmission_interface/SimpleTransmission</type>
		<joint name="second_door_right_joint">
			<hardwareInterface>hardware_interface/EffortJointInterface</hardwareInterface>
		</joint>
		<actuator name="second_door_right_motor">
			<hardwareInterface>hardware_interface/EffortJointInterface</hardwareInterface>
			<mechanicalReduction>1</mechanicalReduction>
		</actuator>
	</transmission> 

<!-- Gazebo Materials-->

    <gazebo reference="shaft">
        <material>Gazebo/Grey</material>
    </gazebo>

    <gazebo reference="car">
        <gravity>0</gravity>
        <material>Gazebo/Grey</material>
    </gazebo>

    <gazebo reference="car_door_left">
        <material>Gazebo/Yellow</material>
    </gazebo>

    <gazebo reference="car_door_right">
        <material>Gazebo/Yellow</material>
    </gazebo>

    <gazebo reference="lobby_door_left">
        <material>Gazebo/Orange</material>
    </gazebo>

    <gazebo reference="lobby_door_right">
        <material>Gazebo/Orange</material>
    </gazebo>

    <gazebo reference="first_door_left">
        <material>Gazebo/Orange</material>
    </gazebo>

    <gazebo reference="first_door_right">
        <material>Gazebo/Orange</material>
    </gazebo>

    <gazebo reference="second_door_left">
        <material>Gazebo/Orange</material>
    </gazebo>

    <gazebo reference="second_door_right">
        <material>Gazebo/Orange</material>
    </gazebo>
</robot>
